Workbook
Name BTL_COM_CLBHA4_CCTEC201: [2]水系统CCS31a90.1!$A$2
Name dianji: [3]泵站各参数表!$H$3:$H$17
Name gaoyaguolvqi: [3]泵站各参数表!$U$3:$U$9
Name huiludaima: '[3]阀组分档-基本数据源'!$I$23:$I$30
Name huiyouguolvqi: [3]泵站各参数表!$Z$3:$Z$9
Name REV_MATERIAL: [2]水系统CCS31a90.1!$D$4
Name REV_MATERIALNAME: [2]水系统CCS31a90.1!$B$4
Name REV_NUMBER: [2]水系统CCS31a90.1!$A$4
Name REV_QTY: [2]水系统CCS31a90.1!$F$4
Name REV_REMARK: [2]水系统CCS31a90.1!$L$4
Name REV_STANDARDNO: [2]水系统CCS31a90.1!$C$4
Name REV_TOTALWEIGHT: [2]水系统CCS31a90.1!$H$4
Name REV_UNIT: [2]水系统CCS31a90.1!$E$4
Name REV_UNITWEIGHT: [2]水系统CCS31a90.1!$G$4
Name xunengqi: [3]泵站各参数表!$AJ$3:$AJ$10
Name xunhuaguolvqi: [3]泵站各参数表!$AE$3:$AE$11
Name xunhuanbeng: [3]泵站各参数表!$M$3:$M$23
Name xunhuanbengdianji: [3]泵站各参数表!$H$3:$H$12
Name youxiang: [3]泵站各参数表!$R$3:$R$15
Name zhubengfuzhudaima: [3]泵站各参数表!$A$3:$A$12
Name ___CFJ1: #REF!
Name __CFJ1: #REF!
Name __F6: #REF!
Name _1F6_: #REF!
Name _CFJ1: #REF!
Name _F6: #REF!
Name ¿°Ä”ÍˆÍ: #REF!
Name A: #REF!
Name aaaa: #REF!
Name FCV_FB: [7]Configuration!$B$19
Name FENG10: #REF!
Name GLB_TT: [7]Configuration!$D$2
Name ltmc: #REF!
Name ltmc2: #REF!
Name ltmc3: #REF!
Name ltmcc: #REF!
Name MatSel: #REF!
Name MatSel_Table: #REF!
Name one: #REF!
Name RH: #REF!
Name Roll_Type_1_dia: #REF!
Name Roll_Type_2_dia: #REF!
Name Roll_Type_3_dia: #REF!
Name Sep_Hide_Column: #REF!
Name Sep_Hide_Marker_Column: #REF!
Name SP_GA_Heater: #REF!
Name SP_HOSE: #REF!
Name SP_Idx_Coating: #REF!
Name SP_Idx_Cooling: #REF!
Name SP_Idx_Furnace: #REF!
Name SP_Idx_Galvanneal: #REF!
Name SP_p_Manometer: #REF!
Name SP_p_Reg: #REF!
Name SP_Steering: #REF!
Name SP_Tensiometer: #REF!
Name SP_Zinc_Pot: #REF!
Name SP_Zinc_Pot_El: #REF!
Name ｘｃ: #REF!
Name xg: #REF!
Name ｿｰﾄ範囲: #REF!

Sheet 表1汇总表
A1: 表1 报 价 汇 总 表
A2: 序号 | B2: 标段 | C2: 工程项目及费用名称 | D2: 报价（元） | E2: 其中：主材费 | F2: 其中：人工费 | G2: 备注
C3: 一、工程费
A4: 1 | B4: 柳钢股份转炉厂二区一罐制及脱硫站升级改造工程(LZG0225J1) | C4: 1：土建工程 | D4: =表2清单!L4 -> 11828964 | E4: =表2清单!M4 -> 5370095.7 | F4: =表2清单!N4 -> 2938281.7
C5: 2：工艺设施 | D5: =表2清单!L69 -> 389815.57 | E5: =表2清单!M69 -> 88500 | F5: =表2清单!N69 -> 206460
C6: 3：燃气设施 | D6: =表2清单!L112 -> 113825.81 | E6: =表2清单!M112 -> 54500 | F6: =表2清单!N112 -> 35340
C7: 4：热力设施 | D7: =表2清单!L126 -> 29099.265 | E7: =表2清单!M126 -> 13500 | F7: =表2清单!N126 -> 9100
C8: 5：给排水设施 | D8: =表2清单!L135 -> 236098.1 | E8: =表2清单!M135 -> 132388 | F8: =表2清单!N135 -> 53648
C9: 6：通风设施 | D9: =表2清单!L147 -> 671715.64 | E9: =表2清单!M147 -> 263900 | F9: =表2清单!N147 -> 219100
C10: 7：电气设施 | D10: =表2清单!L162 -> 1085579 | E10: =表2清单!M162 -> 299805 | F10: =表2清单!N162 -> 479773
C11: 8：电力设施 | D11: =表2清单!L257 -> 142603.46 | E11: =表2清单!M257 -> 30585 | F11: =表2清单!N257 -> 76950
C12: 9：仪表设施 | D12: =表2清单!L267 -> 93942.629 | E12: =表2清单!M267 -> 11088 | F12: =表2清单!N267 -> 59565
C13: 10：计算机 | D13: =表2清单!L300 -> 28643.657 | E13: =表2清单!M300 -> 200 | F13: =表2清单!N300 -> 20880
C14: 11：自动扒渣系统 | D14: =表2清单!L320 -> 30869.754 | E14: =表2清单!M320 -> 6317.3 | F14: =表2清单!N320 -> 17573.4
C15: 12：罐架识别系统 | D15: =表2清单!L338 -> 19043.19 | E15: =表2清单!M338 -> 1602 | F15: =表2清单!N338 -> 13124
C16: 13：电讯设施 | D16: =表2清单!L356 -> 219302.28 | E16: =表2清单!M356 -> 25756 | F16: =表2清单!N356 -> 136668
C17: 14：总图设施 | D17: =表2清单!L377 -> 1290818.4 | E17: =表2清单!M377 -> 428691.06 | F17: =表2清单!N377 -> 204200
C18: 15：拆除 | D18: =表2清单!L389 -> 1912679.1 | E18: =表2清单!M389 -> 2072 | F18: =表2清单!N389 -> 962817.37
C19: 16：测量 | D19: =表2清单!L447 -> 38000 | E19: =表2清单!M447 -> 0 | F19: =表2清单!N447 -> 30000
C20: 工程费用小计 | D20: =SUM(D4:D19) -> 18131000 | E20: =SUM(E4:E19) -> 6729000 | F20: =SUM(F4:F19) -> 5463480.5
C21: 其中：安全文明施工费 | D21: =D20*0.0675 -> 1223842.5
C23: 二、其他费
C27: 合计 | D27: =D20+D23 -> 18131000 | E27: =E20+E23 -> 6729000 | F27: =F20+F23 -> 5463480.5
A28: 投标总报价（大写）： | C28: =ROUND(D27,0) -> 18131000
A30: 投标单位:(盖章)
A32: 法定代表人:(签字、盖章)
A34: 日期 ： 年 月 日

Sheet 表2清单
A1: 流水号 | B1: 序号 | C1: 工程或费用名称 | D1: 规格型号 | E1: 单位 | F1: 数 量 | G1: 重量(吨) | I1: 单价（元） | L1: 总价（元） | O1: 主材损耗率% | P1: 工作内容 | U1: 单价（元）
G2: 单重 | H2: 总重 | I2: 综合单价 | J2: 其中： | L2: 总计 | M2: 其中： | U2: 综合单价
J3: 主材单价 | K3: 人工费 | M3: 主材总价 | N3: 人工费总价
A4: =ROW()-4 -> 0 | B4: 1 | C4: 土建设施 | L4: =SUM(L5:L68) -> 11828964 | M4: =SUM(M5:M68) -> 5370095.7 | N4: =SUM(N5:N68) -> 2938281.7
A5: 1 | B5: 1.1 | C5: 新建脱硫主厂房
A6: 2 | B6: 1.1.1 | C6: 脱硫厂房基础 | D6: C30(钢筋单列) | E6: 立方米 | F6: 120 | I6: 794.40165 | J6: 260 | K6: 192.5 | L6: =F6*I6 -> 95328.198 | M6: =F6*J6 -> 31200 | N6: =F6*K6 -> 23100 | P6: 降水、排水、挖填运土石方(含特殊爆破)、基础垫层、模板安拆堆放、截（接）桩头、填桩芯、预埋铁件（含钢管、套筒、防雷接地极、地脚螺栓等）制安、砼浇捣养护、脚手架搭拆、铁件刷油、浇灌（灌浆）、固定架制安等全部工作内容 | U6: 794.40165 | V6: =I6-U6 -> 0 | W6: =I6-J6 -> 534.40165
A7: 3 | B7: 1.1.2 | C7: 脱硫厂房基础钢筋 | D7: 各种规格、各种型号、各种材质 | E7: 吨 | F7: 9 | I7: 5161 | J7: 3250 | K7: 850 | L7: =F7*I7 -> 46449 | M7: =F7*J7 -> 29250 | N7: =F7*K7 -> 7650 | P7: 钢筋采购、制作、运输、绑扎安装等全部工作内容 | Q7: 主材贵300 施工贵100 | U7: 5361.3917 | V7: =I7-U7 -> -200.39168 | W7: =I7-J7 -> 1911
A8: 4 | B8: 1.1.3 | C8: 脱硫主厂房钢结构 | D8: 各种规格、各种型号、各种材质 | E8: 吨 | F8: 209 | I8: 7251.5786 | J8: 3510 | K8: 2150 | L8: =F8*I8 -> 1515579.9 | M8: =F8*J8 -> 733590 | N8: =F8*K8 -> 449350 | P8: 钢结构设计详图设计、材料供货、除锈防腐、制作、探伤、运输、卸车、拼装、吊装、安装、涂漆、接地等全部工作内容 | Q8: 7000 | R8: 主材贵 3-4点损耗 | U8: 7551.5786 | V8: =I8-U8 -> -300 | W8: =I8-J8 -> 3741.5786
A9: 5 | B9: 1.1.4 | C9: 屋面彩板 | D9: 屋面采用0.8mm厚单层YX130-333-666（角驰III）型彩色压型钢板 | E9: 平方米 | F9: 1536 | I9: 127.02185 | J9: 72 | K9: 22 | L9: =F9*I9 -> 195105.56 | M9: =F9*J9 -> 110592 | N9: =F9*K9 -> 33792 | P9: 墙屋面板(含异型板、零配件)排版、制作、运输、安装等施工图、施工规范要求的全部工作内容 | U9: 127.02185 | V9: =I9-U9 -> 0 | W9: =I9-J9 -> 55.021848
A10: 6 | B10: 1.1.5 | C10: 雨棚彩板 | D10: 0.8厚V125彩钢板 | E10: 平方米 | F10: 22.32 | I10: 115.60868 | J10: 63.5 | K10: 22 | L10: =F10*I10 -> 2580.3857 | M10: =F10*J10 -> 1417.32 | N10: =F10*K10 -> 491.04 | P10: 同上 | U10: 115.60868 | V10: =I10-U10 -> 0 | W10: =I10-J10 -> 52.10868
A11: 7 | B11: 1.1.6 | C11: 外墙彩板 | D11: 0.6厚V125彩钢板 | E11: 平方米 | F11: 3410 | I11: 108.15325 | J11: 50.5 | K11: 22 | L11: =F11*I11 -> 368802.57 | M11: =F11*J11 -> 172205 | N11: =F11*K11 -> 75020 | P11: 同上 | U11: 98.153246 | V11: =I11-U11 -> 10 | W11: =I11-J11 -> 57.653246
A12: 8 | B12: 1.1.7 | C12: 外墙采光板 | D12: 1.5mm厚FRP一级阻燃型增强玻璃钢釆光板，板型同墙面 | E12: 平方米 | F12: 420 | I12: 57.200113 | J12: 20 | K12: 22 | L12: =F12*I12 -> 24024.048 | M12: =F12*J12 -> 8400 | N12: =F12*K12 -> 9240 | P12: 同上 | U12: 57.200113 | V12: =I12-U12 -> 0 | W12: =I12-J12 -> 37.200113
A13: 9 | B13: 1.1.8 | C13: TPO防水卷材 | D13: 1.5厚，燃烧性能等级不低于B2，卷材随波形铺设。 | E13: 平方米 | F13: 1558.32 | I13: 64.015136 | J13: 41 | K13: 10 | L13: =F13*I13 -> 99756.066 | M13: =F13*J13 -> 63891.12 | N13: =F13*K13 -> 15583.2 | P13: 基层处理、涂刷基层处理剂、卷材铺设、收口密封、成品保护等全部工作内容 | Q13: 主材填报 | U13: 64.015136 | V13: =I13-U13 -> 0 | W13: =I13-J13 -> 23.015136
A14: 10 | B14: 1.1.9 | C14: 砖墙 | D14: 烧结普通砖 | E14: 立方米 | F14: 30 | I14: 1208.7664 | J14: 436 | K14: 520 | L14: =F14*I14 -> 36262.992 | M14: =F14*J14 -> 13080 | N14: =F14*K14 -> 15600 | P14: 调运砂浆、运砌砖、砌窗台虎头砖、腰线、门窗套、安放木砖、铁件、粉刷、涂料、脚手架等满足施工图、施工规范要求的全部工作内容 | Q14: 主材填报 | U14: 1208.7664 | V14: =I14-U14 -> 0 | W14: =I14-J14 -> 772.7664
A15: 11 | B15: 1.1.10 | C15: 电动钢卷帘门 | D15: 高5m，宽4m，钢制卷帘门 | E15: 平方米 | F15: 36 | I15: 261.71961 | J15: 200 | K15: 30 | L15: =F15*I15 -> 9421.906 | M15: =F15*J15 -> 7200 | N15: =F15*K15 -> 1080 | P15: 材料供货及敷设安装等满足施工图纸及规范要求的全部工作内容 | U15: 261.71961 | V15: =I15-U15 -> 0 | W15: =I15-J15 -> 61.719611
A16: 12 | B16: 1.1.11 | C16: 钢制防盗门 | D16: 50mm厚 | E16: 平方米 | F16: 12.32 | I16: 495.68956 | J16: 330 | K16: 100 | L16: =F16*I16 -> 6106.8953 | M16: =F16*J16 -> 4065.6 | N16: =F16*K16 -> 1232 | P16: 同上 | U16: 495.68956 | V16: =I16-U16 -> 0 | W16: =I16-J16 -> 165.68956
A17: 13 | B17: 1.1.12 | C17: 铝合金推拉窗 | E17: 平方米 | F17: 90 | I17: 298.19699 | J17: 210 | K17: 50 | L17: =F17*I17 -> 26837.729 | M17: =F17*J17 -> 18900 | N17: =F17*K17 -> 4500 | P17: 同上 | U17: 298.19699 | V17: =I17-U17 -> 0 | W17: =I17-J17 -> 88.196991
A18: 14 | B18: 1.1.13 | C18: 散水 | D18: 1、80厚C20混凝土面层,撤1:1水泥砂子压实赶光；2、150厚粒径10~40砾石灌M2.5混合砂浆或150厚3:7灰土 夯实,宽出面层100；3、压实填土,压实系数>93%,向外坡3%~5% | E18: 平方米 | F18: 124.8 | I18: 71.699369 | J18: 17.2 | K18: 20 | L18: =F18*I18 -> 8948.0812 | M18: =F18*J18 -> 2146.56 | N18: =F18*K18 -> 2496 | P18: 降水、排水、挖运填土石方、铺设垫层、夯实、模板安拆、浇筑混凝土面层抹灰压实、养护等全部工作内容 | U18: 71.699369 | V18: =I18-U18 -> 0 | W18: =I18-J18 -> 54.499369
A19: 15 | B19: 1.1.14 | C19: 建筑地坪 | D19: 150厚C20素混凝土，垫层300厚碎石 | E19: 平方米 | F19: 700 | I19: 121.52126 | J19: 32.25 | K19: 25 | L19: =F19*I19 -> 85064.882 | M19: =F19*J19 -> 22575 | N19: =F19*K19 -> 17500 | P19: 降水、排水、挖填运土石方(含特殊爆破)、基础垫层、造型砼、模板安拆堆放、截（接）桩头、填桩芯、预埋铁件（含钢管、套筒、防雷接地极、地脚螺栓等）制安、砼浇捣养护、脚手架搭拆、铁件刷油、浇灌（灌浆）、固定架制安等全部工作内容 | U19: 121.52126 | V19: =I19-U19 -> 0 | W19: =I19-J19 -> 89.27126
A20: 16 | B20: 1.2 | C20: 脱硫站平台 | I20: 0 | J20: 0 | K20: 0 | L20: =F20*I20 -> 0 | M20: =F20*J20 -> 0 | N20: =F20*K20 -> 0 | U20: 0 | V20: =I20-U20 -> 0 | W20: =I20-J20 -> 0
A21: 17 | B21: 1.2.1 | C21: 脱硫平台柱基础 | D21: C30(钢筋单列) | E21: 立方米 | F21: 130 | I21: 784.60255 | J21: 260 | K21: 192.5 | L21: =F21*I21 -> 101998.33 | M21: =F21*J21 -> 33800 | N21: =F21*K21 -> 25025 | P21: 降水、排水、挖填运土石方(含特殊爆破)、基础垫层、模板安拆堆放、截（接）桩头、填桩芯、预埋铁件（含钢管、套筒、防雷接地极、地脚螺栓等）制安、砼浇捣养护、脚手架搭拆、铁件刷油、浇灌（灌浆）、固定架制安等全部工作内容 | U21: 784.60255 | V21: =I21-U21 -> 0 | W21: =I21-J21 -> 524.60255
A22: 18 | B22: 1.2.2 | C22: 脱硫站平台钢筋混凝土框架 | D22: C30耐热钢筋混凝土，耐热温度250度(钢筋单列) | E22: 立方米 | F22: 314 | I22: 1499.6903 | J22: 570.75 | K22: 415 | L22: =F22*I22 -> 470902.75 | M22: =F22*J22 -> 179215.5 | N22: =F22*K22 -> 130310 | P22: 同上 | U22: 1499.6903 | V22: =I22-U22 -> 0 | W22: =I22-J22 -> 928.94029
A23: 19 | B23: 1.2.3 | C23: 以上钢筋 | D23: 各种规格、各种型号、各种材质 | E23: 吨 | F23: 60 | I23: 5161 | J23: 3250 | K23: 850 | L23: =F23*I23 -> 309660 | M23: =F23*J23 -> 195000 | N23: =F23*K23 -> 51000 | P23: 钢筋采购、制作、运输、绑扎安装等全部工作内容 | U23: 5361.3917 | V23: =I23-U23 -> -200.39168 | W23: =I23-J23 -> 1911
A24: 20 | B24: 1.2.4 | C24: 脱硫站平台钢结构 | D24: 各种规格、各种型号、各种材质 | E24: 吨 | F24: 408 | I24: 7251.5786 | J24: 3510 | K24: 2150 | L24: =F24*I24 -> 2958644.1 | M24: =F24*J24 -> 1432080 | N24: =F24*K24 -> 877200 | P24: 钢结构设计详图设计、材料供货、除锈防腐、隔热、制作、探伤、运输、卸车、拼装、吊装、安装、涂漆、接地等全部工作内容 | U24: 7551.5786 | V24: =I24-U24 -> -300 | W24: =I24-J24 -> 3741.5786
A25: 21 | B25: 1.2.5 | C25: 高位料仓 | D25: 各种规格、各种型号、各种材质 | E25: 吨 | F25: 15 | I25: 7691.5802 | J25: 3910 | K25: 2150 | L25: =F25*I25 -> 115373.7 | M25: =F25*J25 -> 58650 | N25: =F25*K25 -> 32250 | P25: 同上 | U25: 7691.5802 | V25: =I25-U25 -> 0 | W25: =I25-J25 -> 3781.5802
A26: 22 | B26: 1.2.6 | C26: 平台隔热喷涂料 | D26: 隔热板下部及侧向外表面喷涂 50mm厚隔热材料, 要求耐火度不小于700度，材料容重不大于1t/m3 | E26: m³ | F26: 25 | I26: 4678.28 | J26: 2200 | K26: 1500 | L26: =F26*I26 -> 116957 | M26: =F26*J26 -> 55000 | N26: =F26*K26 -> 37500 | P26: 供货、接货、开箱清点、场内运输、检、试验、（含外观、理化等检、试验）、铺贴喷隔热材料及配套的固定件、清理表面等全部工作内容 | Q26: 添主材 | U26: 4678.28 | V26: =I26-U26 -> 0 | W26: =I26-J26 -> 2478.28
A27: 23 | B27: 1.2.7 | C27: 耐火砖 | D27: 高铝砖、硅碳砖‌、镁碳砖；1550℃ | E27: 立方米 | F27: 30 | I27: 2275.92 | J27: 1500 | K27: 300 | L27: =F27*I27 -> 68277.6 | M27: =F27*J27 -> 45000 | N27: =F27*K27 -> 9000 | P27: 供货，接货、开箱清点、运输、检（试）验、（含外观、理化等检、试验）、砌筑（含预砌筑、预组装、选砖、机械集中磨砖、机械集中切砖）、二次勾缝吹风清扫、镶铁件、模板装拆等全部工作内容 | Q27: 添主材 | U27: 2275.92 | V27: =I27-U27 -> 0 | W27: =I27-J27 -> 775.92
A28: 24 | B28: 1.3 | C28: 脱硫站轨道及基础 | I28: 0 | J28: 0 | K28: 0 | L28: =F28*I28 -> 0 | M28: =F28*J28 -> 0 | N28: =F28*K28 -> 0 | U28: 0 | V28: =I28-U28 -> 0 | W28: =I28-J28 -> 0
A29: 25 | B29: 1.3.1 | C29: 轨道基础 | D29: C30(钢筋单列) | E29: 立方米 | F29: 495 | I29: 901.55955 | J29: 260 | K29: 235 | L29: =F29*I29 -> 446271.98 | M29: =F29*J29 -> 128700 | N29: =F29*K29 -> 116325 | P29: 降水、排水、挖填运土石方(含特殊爆破)、基础垫层、模板安拆堆放、截（接）桩头、填桩芯、预埋铁件（含钢管、套筒、防雷接地极、地脚螺栓等）制安、砼浇捣养护、脚手架搭拆、铁件刷油、浇灌（灌浆）、固定架制安等全部工作内容 | U29: 901.55955 | V29: =I29-U29 -> 0 | W29: =I29-J29 -> 641.55955
A30: 26 | B30: 1.3.2 | C30: 轨道基础钢筋 | D30: 各种规格、各种型号、各种材质 | E30: 吨 | F30: 59.4 | I30: 5161 | J30: 3250 | K30: 850 | L30: =F30*I30 -> 306563.4 | M30: =F30*J30 -> 193050 | N30: =F30*K30 -> 50490 | P30: 钢筋采购、制作、运输、绑扎安装等全部工作内容 | U30: 5361.3917 | V30: =I30-U30 -> -200.39168 | W30: =I30-J30 -> 1911
A31: 27 | B31: 1.3.3 | C31: 地面钢轨 | D31: 各种规格、各种型号、各种材质 | E31: 吨 | F31: 23.27 | I31: 8055.235 | J31: 4600 | K31: 1300 | L31: =F31*I31 -> 187445.32 | M31: =F31*J31 -> 107042 | N31: =F31*K31 -> 30251 | P31: 矫直、切割、坡口、吊装、手下工焊接、找正、连接接头、压轨器(含主材)供货及安装、车挡制作、接地安装等全部工作内容 | U31: 8055.235 | V31: =I31-U31 -> 0 | W31: =I31-J31 -> 3455.235
A32: 28 | B32: 1.3.4 | C32: 电缆卷筒钢平台 | D32: 各种规格、各种型号、各种材质 | E32: 吨 | F32: 2 | I32: 7551.5786 | J32: 3910 | K32: 2150 | L32: =F32*I32 -> 15103.157 | M32: =F32*J32 -> 7820 | N32: =F32*K32 -> 4300 | P32: 钢结构设计详图设计、材料供货、除锈防腐、制作、探伤、运输、卸车、拼装、吊装、安装、涂漆、接地等全部工作内容 | U32: 7551.5786 | V32: =I32-U32 -> 0 | W32: =I32-J32 -> 3641.5786
A33: 29 | B33: 1.4 | C33: 新建参观通道 | I33: 0 | J33: 0 | K33: 0 | L33: =F33*I33 -> 0 | M33: =F33*J33 -> 0 | N33: =F33*K33 -> 0 | U33: 0 | V33: =I33-U33 -> 0 | W33: =I33-J33 -> 0
A34: 30 | B34: 1.4.1 | C34: 精炼炉及脱硫走道钢平台 | D34: 各种规格、各种型号、各种材质 | E34: 吨 | F34: 14 | I34: 7551.5786 | J34: 3910 | K34: 2150 | L34: =F34*I34 -> 105722.1 | M34: =F34*J34 -> 54740 | N34: =F34*K34 -> 30100 | P34: 钢结构设计详图设计、材料供货、除锈防腐、制作、探伤、运输、卸车、拼装、吊装、安装、涂漆、接地等全部工作内容 | U34: 7551.5786 | V34: =I34-U34 -> 0 | W34: =I34-J34 -> 3641.5786
A35: 31 | B35: 1.4.2 | C35: 屋面彩板 | D35: 0.8厚V125彩钢板 | E35: 平方米 | F35: 60 | I35: 127.02185 | J35: 72 | K35: 22 | L35: =F35*I35 -> 7621.3109 | M35: =F35*J35 -> 4320 | N35: =F35*K35 -> 1320 | P35: 墙屋面板(含异型板、零配件)排版、制作、运输、安装等施工图、施工规范要求的全部工作内容 | U35: 127.02185 | V35: =I35-U35 -> 0 | W35: =I35-J35 -> 55.021848
A36: 32 | B36: 1.4.3 | C36: 墙面彩板 | D36: 0.6厚V125彩钢板 | E36: 平方米 | F36: 30 | I36: 115.60868 | J36: 63.5 | K36: 22 | L36: =F36*I36 -> 3468.2604 | M36: =F36*J36 -> 1905 | N36: =F36*K36 -> 660 | P36: 同上 | U36: 115.60868 | V36: =I36-U36 -> 0 | W36: =I36-J36 -> 52.10868
A37: 33 | B37: 1.4.4 | C37: 钢化玻璃隔断 | D37: 单层钢化玻璃，不小于6mm | E37: 平方米 | F37: 120 | I37: 584.19756 | J37: 330 | K37: 120 | L37: =F37*I37 -> 70103.707 | M37: =F37*J37 -> 39600 | N37: =F37*K37 -> 14400 | P37: 供货、运输、安装、调试等全部工作内容 | U37: 584.19756 | V37: =I37-U37 -> 0 | W37: =I37-J37 -> 254.19756
A38: 34 | B38: 1.5 | C38: 建筑小房 | I38: 0 | J38: 0 | K38: 0 | L38: =F38*I38 -> 0 | M38: =F38*J38 -> 0 | N38: =F38*K38 -> 0 | U38: 0 | V38: =I38-U38 -> 0 | W38: =I38-J38 -> 0
A39: 35 | B39: 1.5.1 | C39: 液压站 | D39: 砖混结构 | E39: 平方米 | F39: 47.25 | I39: 2640.0224 | J39: 800 | K39: 680 | L39: =F39*I39 -> 124741.06 | M39: =F39*J39 -> 37800 | N39: =F39*K39 -> 32130 | P39: 降水、排水、土石方(含特殊爆破)挖运填、基础、截（接）桩头、桩锚筋、桩锚板、PHC桩混凝土填芯、基坑支护、钢筋供货及制安、混凝土结构（含构件）、砌体及其涂料，楼面顶棚涂料，楼面、屋面及其防水、防火、隔热、保温层，门窗，地面防潮层，地面铺砌、预埋铁件、预埋管道、钢构件、钢结构KMD设计、脚手架，界面剂，伸缩缝，隔断，踢脚线、散水、坡道、装修及零星构筑物(如电缆沟及其盖板)等全部土建工作内容及照明(包括照明电缆电线、配管、灯具、整流器（断路器、触发器）、开关、插座、照明箱等主材供货及安装等) 、防雷接地、室内外给排水（含淋浴、洗脸盆、污水池、大小便器、管道等），空调电源线路、弱电线路及插座等全部工作内容 | U39: 2640.0224 | V39: =I39-U39 -> 0 | W39: =I39-J39 -> 1840.0224
A40: 36 | B40: 1.5.2 | C40: 操作室（精装修） | D40: 砖混结构 | E40: 平方米 | F40: 63 | I40: 2892.9024 | J40: 800 | K40: 680 | L40: =F40*I40 -> 182252.85 | M40: =F40*J40 -> 50400 | N40: =F40*K40 -> 42840 | P40: 同上 | U40: 2892.9024 | V40: =I40-U40 -> 0 | W40: =I40-J40 -> 2092.9024
...

Sheet 表3
A1: 表3 工程量清单偏差报价表
A2: 表3 工程量清单偏差报价表（分标段）
A3: 序号 | B3: 工程项目及费用名称 | C3: 规格型号 | D3: 单位 | E3: 重量(t) | G3: 单价（元） | J3: 合价（元） | M3: 主材损耗率%
E4: 单重 | F4: 总 重 | G4: 综合单价(元) | H4: 其中：主材单价 | J4: 合价(元) | K4: 其中：主材合价 | L4: 其中
I5: 其中 | L5: ：人工费
I6: ：人工费
B7: 无
B15: 合计（结转至表1报价汇总表）
A16: 注：没有偏差，请在此表中写无。如有偏差，只填写对应的子项号、工程项目及费用名称及其内容。

Sheet 表4
A1: 表4. 现场因素、施工技术措施及施工措施费用报价表
A2: 表4 现场因素、施工技术措施及施工措施费用报价表（分标段）
A3: 序号 | B3: 计价内容及计算过程 | C3: 金额，元 | D3: 备注
A4: 无
A11: 共 页，本页小计 0 元
A12: 合计
A13: 税金
A14: 合计 0元（结转至表1报价汇总表）
A16: 投标单位：（盖章）
A17: 法定代表人：（签字、盖章）
A18: 日期 ： 年 月 日

Sheet 表5
A1: 表5 安全文明施工费
A2: 标段 | B2: 序号 | C2: 工程项目及费用名称 | D2: 单位 | E2: 数量 | F2: 单价(元） | G2: 总价（元） | H2: 备注
A3: 辛集澳森2#连铸机改造工程 (安装标段) | B3: 1 | C3: 环境保护 | G3: =G14*0.15 -> 183576.45
C4: 烟尘处理设备采购、使用
B5: 2 | C5: 安全生产/施工 | G5: =G14*0.3 -> 367152.9 | H5: 明细详见表6
B8: 3 | C8: 文明施工 | G8: =G14*0.3 -> 367152.9
C9: 办公、生活区卫生
C10: 材料堆放区整理、标准化标识
B11: 4 | C11: 临时设施 | G11: =G14*0.25 -> 305960.75
C12: 施工场地围栏、围挡
C13: 现场办公、材料堆放区设施
C14: 合计 | G14: =ROUND(表1汇总表!D21,0) -> 1223843
A15: 投标单位：（盖章）
A16: 法定代表人：（签字、盖章）
A17: 日期 ： 年 月 日

Sheet 表6
A1: 表6 安全生产费用清单
A2: 安全生产费用清单
A3: 类别 | B3: 明细 | C3: 单位 | D3: 数量 | E3: 单价（元） | F3: 金额（元） | G3: 备注
A4: 一、完善、改造和维护安全防护设施设备支出（不含“三同时”要求初期投入的安全设施），包括施工现场临时用电系统、洞口、临边、机械设备安全装置、高处作业防护、交叉作业防护、防火、防爆、防尘、防毒、防雷、防台风、防地质灾害、安全警示牌和标识牌、安全图板、安全防护棚、围挡、地下工程有害气体监测、通风、临时安全防护等设施设备支出，简称为“安全设施费” | B4: 临时临边防护栏 | C4: m | D4: 450 | E4: 65 | F4: =E4*D4 -> 29250
B5: 孔洞盖板 | C5: m2 | D5: 100 | E5: 150 | F5: =E5*D5 -> 15000
B6: 密目网 | C6: m2 | D6: 807 | E6: 15 | F6: =E6*D6 -> 12105
B7: 防坠网 | C7: m2 | D7: 200 | E7: 10 | F7: =E7*D7 -> 2000
B8: 防坠器 | C8: 个
B9: 安全绳（φ12mm） | C9: m | D9: 300 | E9: 2.5 | F9: =E9*D9 -> 750
B10: 轴流风机 | C10: 台 | D10: 15 | E10: 310 | F10: =E10*D10 -> 4650
B11: 施工围挡 | C11: m | D11: 150 | E11: 110 | F11: =E11*D11 -> 16500 | G11: 规格参照标准化手册
B12: 文明施工图牌 | C12: 块 | D12: 13 | E12: 160 | F12: =E12*D12 -> 2080
B13: 室内责任制牌 | C13: 块 | D13: 13 | E13: 160 | F13: =E13*D13 -> 2080
B14: 安全警示牌 | C14: 块 | D14: 15 | E14: 160 | F14: =E14*D14 -> 2400
B15: 气瓶固定装置（拖车） | C15: 个 | D15: 10 | E15: 120 | F15: =E15*D15 -> 1200
B16: 临电配电箱 | C16: 箱 | D16: 10 | E16: 1000 | F16: =E16*D16 -> 10000
B17: 临电配电线路 | C17: 米 | D17: 200 | E17: 20 | F17: =E17*D17 -> 4000
B18: ······ | F18: =E18*D18 -> 0
A19: 二、配备、维护、保养应急救援器材、设备支出和应急救援队伍建设、应急预案制定与应急演练支出，简称为“应急救援费” | B19: 灭火器 | C19: 具 | D19: 20 | E19: 70 | F19: =E19*D19 -> 1400
B20: 应急演练 | C20: 次 | D20: 20 | E20: 400 | F20: =E20*D20 -> 8000
B21: 应急药包 | C21: 个 | D21: 20 | E21: 200 | F21: =E21*D21 -> 4000
B22: ······ | F22: =E22*D22 -> 0
A23: 三、开展重大危险源检测、评估、监控支出，安全生产风险分级管控和事故隐患整改支出，安全生产信息化建设、运维支出，简称为“风险控制费” | B23: 隐患整改费用 | C23: 次 | D23: 40 | E23: 3000 | F23: =E23*D23 -> 120000
B24: ······ | F24: =E24*D24 -> 0
A25: 四、安全生产检查、评价（不包括新建、改建、扩建项目安全评价）、咨询和标准化建设支出，简称为“检查评价费” | B25: 检查支出 | C25: 次 | D25: 40 | E25: 1000 | F25: =E25*D25 -> 40000
B26: ······ | F26: =E26*D26 -> 0
A27: 五、配备和更新现场作业人员安全防护用品支出，简称为“防护用品费” | B27: 工作服 | C27: 套 | D27: 150 | E27: =60+53.548 -> 113.548 | F27: =E27*D27 -> 17032.2
B28: 安全帽 | C28: 顶 | D28: 150 | E28: 35 | F28: =E28*D28 -> 5250
B29: 劳保鞋 | C29: 双 | D29: 150 | E29: 35 | F29: =E29*D29 -> 5250
B30: 安全带 | C30: 副 | D30: 150 | E30: 30 | F30: =E30*D30 -> 4500
B31: 焊工手套 | C31: 双 | D31: 150 | E31: 5 | F31: =E31*D31 -> 750
B32: 焊工面罩 | C32: 个 | D32: 150 | E32: 50 | F32: =E32*D32 -> 7500
B33: 护目镜 | C33: 个 | D33: 150 | E33: 10 | F33: =E33*D33 -> 1500
B34: 电工手套 | C34: 双 | D34: 150 | E34: 5 | F34: =E34*D34 -> 750
B35: 电工绝缘劳保鞋 | C35: 双 | D35: 150 | E35: 50 | F35: =E35*D35 -> 7500
B36: 普通手套 | C36: 双 | D36: 150 | E36: 3 | F36: =E36*D36 -> 450
B37: 工业防尘口罩 | C37: 个 | D37: 150 | E37: 2 | F37: =E37*D37 -> 300
B38: 耳塞 | C38: 对 | D38: 150 | E38: 3 | F38: =E38*D38 -> 450
B39: ······ | F39: =E39*D39 -> 0
A40: 六、安全生产宣传、教育、培训和从业人员发现并报告事故隐患的奖励支出，简称为“宣传教育费” | B40: 培训费 | C40: 人 | D40: 150 | E40: 30 | F40: =E40*D40 -> 4500
...

Sheet Sheet1
A1: 流水号 | B1: 序号 | C1: 工程或费用名称 | D1: 规格型号 | E1: 单位 | F1: 数 量 | G1: 重量(吨) | H1: 列1 | I1: 综合单价 | J1: 主材单价 | K1: 人工费 | L1: 总计 | M1: 主材总价 | N1: 人工费总价 | O1: 主材损耗率% | P1: 工作内容
A2: 0 | B2: 1 | C2: 土建设施 | L2: 11828964 | M2: 5370095.7 | N2: 2938281.7
A3: 1 | B3: 1.1 | C3: 新建脱硫主厂房
A4: 2 | B4: 1.1.1 | C4: 脱硫厂房基础 | D4: C30(钢筋单列) | E4: 立方米 | F4: 120 | I4: 794.40165 | J4: 260 | K4: 192.5 | L4: 95328.198 | M4: 31200 | N4: 23100 | P4: 降水、排水、挖填运土石方(含特殊爆破)、基础垫层、模板安拆堆放、截（接）桩头、填桩芯、预埋铁件（含钢管、套筒、防雷接地极、地脚螺栓等）制安、砼浇捣养护、脚手架搭拆、铁件刷油、浇灌（灌浆）、固定架制安等全部工作内容
A5: 3 | B5: 1.1.2 | C5: 脱硫厂房基础钢筋 | D5: 各种规格、各种型号、各种材质 | E5: 吨 | F5: 9 | I5: 5161 | J5: 3250 | K5: 850 | L5: 46449 | M5: 29250 | N5: 7650 | P5: 钢筋采购、制作、运输、绑扎安装等全部工作内容
A6: 4 | B6: 1.1.3 | C6: 脱硫主厂房钢结构 | D6: 各种规格、各种型号、各种材质 | E6: 吨 | F6: 209 | I6: 7251.5786 | J6: 3510 | K6: 2150 | L6: 1515579.9 | M6: 733590 | N6: 449350 | P6: 钢结构设计详图设计、材料供货、除锈防腐、制作、探伤、运输、卸车、拼装、吊装、安装、涂漆、接地等全部工作内容
A7: 5 | B7: 1.1.4 | C7: 屋面彩板 | D7: 屋面采用0.8mm厚单层YX130-333-666（角驰III）型彩色压型钢板 | E7: 平方米 | F7: 1536 | I7: 127.02185 | J7: 72 | K7: 22 | L7: 195105.56 | M7: 110592 | N7: 33792 | P7: 墙屋面板(含异型板、零配件)排版、制作、运输、安装等施工图、施工规范要求的全部工作内容
A8: 6 | B8: 1.1.5 | C8: 雨棚彩板 | D8: 0.8厚V125彩钢板 | E8: 平方米 | F8: 22.32 | I8: 115.60868 | J8: 63.5 | K8: 22 | L8: 2580.3857 | M8: 1417.32 | N8: 491.04 | P8: 同上
A9: 7 | B9: 1.1.6 | C9: 外墙彩板 | D9: 0.6厚V125彩钢板 | E9: 平方米 | F9: 3410 | I9: 108.15325 | J9: 50.5 | K9: 22 | L9: 368802.57 | M9: 172205 | N9: 75020 | P9: 同上
A10: 8 | B10: 1.1.7 | C10: 外墙采光板 | D10: 1.5mm厚FRP一级阻燃型增强玻璃钢釆光板，板型同墙面 | E10: 平方米 | F10: 420 | I10: 57.200113 | J10: 20 | K10: 22 | L10: 24024.048 | M10: 8400 | N10: 9240 | P10: 同上
A11: 9 | B11: 1.1.8 | C11: TPO防水卷材 | D11: 1.5厚，燃烧性能等级不低于B2，卷材随波形铺设。 | E11: 平方米 | F11: 1558.32 | I11: 64.015136 | J11: 41 | K11: 10 | L11: 99756.066 | M11: 63891.12 | N11: 15583.2 | P11: 基层处理、涂刷基层处理剂、卷材铺设、收口密封、成品保护等全部工作内容
A12: 10 | B12: 1.1.9 | C12: 砖墙 | D12: 烧结普通砖 | E12: 立方米 | F12: 30 | I12: 1208.7664 | J12: 436 | K12: 520 | L12: 36262.992 | M12: 13080 | N12: 15600 | P12: 调运砂浆、运砌砖、砌窗台虎头砖、腰线、门窗套、安放木砖、铁件、粉刷、涂料、脚手架等满足施工图、施工规范要求的全部工作内容
A13: 11 | B13: 1.1.10 | C13: 电动钢卷帘门 | D13: 高5m，宽4m，钢制卷帘门 | E13: 平方米 | F13: 36 | I13: 261.71961 | J13: 200 | K13: 30 | L13: 9421.906 | M13: 7200 | N13: 1080 | P13: 材料供货及敷设安装等满足施工图纸及规范要求的全部工作内容
A14: 12 | B14: 1.1.11 | C14: 钢制防盗门 | D14: 50mm厚 | E14: 平方米 | F14: 12.32 | I14: 495.68956 | J14: 330 | K14: 100 | L14: 6106.8953 | M14: 4065.6 | N14: 1232 | P14: 同上
A15: 13 | B15: 1.1.12 | C15: 铝合金推拉窗 | E15: 平方米 | F15: 90 | I15: 298.19699 | J15: 210 | K15: 50 | L15: 26837.729 | M15: 18900 | N15: 4500 | P15: 同上
A16: 14 | B16: 1.1.13 | C16: 散水 | D16: 1、80厚C20混凝土面层,撤1:1水泥砂子压实赶光；2、150厚粒径10~40砾石灌M2.5混合砂浆或150厚3:7灰土 夯实,宽出面层100；3、压实填土,压实系数>93%,向外坡3%~5% | E16: 平方米 | F16: 124.8 | I16: 71.699369 | J16: 17.2 | K16: 20 | L16: 8948.0812 | M16: 2146.56 | N16: 2496 | P16: 降水、排水、挖运填土石方、铺设垫层、夯实、模板安拆、浇筑混凝土面层抹灰压实、养护等全部工作内容
A17: 15 | B17: 1.1.14 | C17: 建筑地坪 | D17: 150厚C20素混凝土，垫层300厚碎石 | E17: 平方米 | F17: 700 | I17: 121.52126 | J17: 32.25 | K17: 25 | L17: 85064.882 | M17: 22575 | N17: 17500 | P17: 降水、排水、挖填运土石方(含特殊爆破)、基础垫层、造型砼、模板安拆堆放、截（接）桩头、填桩芯、预埋铁件（含钢管、套筒、防雷接地极、地脚螺栓等）制安、砼浇捣养护、脚手架搭拆、铁件刷油、浇灌（灌浆）、固定架制安等全部工作内容
A18: 16 | B18: 1.2 | C18: 脱硫站平台 | I18: 0 | J18: 0 | K18: 0 | L18: 0 | M18: 0 | N18: 0
A19: 17 | B19: 1.2.1 | C19: 脱硫平台柱基础 | D19: C30(钢筋单列) | E19: 立方米 | F19: 130 | I19: 784.60255 | J19: 260 | K19: 192.5 | L19: 101998.33 | M19: 33800 | N19: 25025 | P19: 降水、排水、挖填运土石方(含特殊爆破)、基础垫层、模板安拆堆放、截（接）桩头、填桩芯、预埋铁件（含钢管、套筒、防雷接地极、地脚螺栓等）制安、砼浇捣养护、脚手架搭拆、铁件刷油、浇灌（灌浆）、固定架制安等全部工作内容
A20: 18 | B20: 1.2.2 | C20: 脱硫站平台钢筋混凝土框架 | D20: C30耐热钢筋混凝土，耐热温度250度(钢筋单列) | E20: 立方米 | F20: 314 | I20: 1499.6903 | J20: 570.75 | K20: 415 | L20: 470902.75 | M20: 179215.5 | N20: 130310 | P20: 同上
A21: 19 | B21: 1.2.3 | C21: 以上钢筋 | D21: 各种规格、各种型号、各种材质 | E21: 吨 | F21: 60 | I21: 5161 | J21: 3250 | K21: 850 | L21: 309660 | M21: 195000 | N21: 51000 | P21: 钢筋采购、制作、运输、绑扎安装等全部工作内容
A22: 20 | B22: 1.2.4 | C22: 脱硫站平台钢结构 | D22: 各种规格、各种型号、各种材质 | E22: 吨 | F22: 408 | I22: 7251.5786 | J22: 3510 | K22: 2150 | L22: 2958644.1 | M22: 1432080 | N22: 877200 | P22: 钢结构设计详图设计、材料供货、除锈防腐、隔热、制作、探伤、运输、卸车、拼装、吊装、安装、涂漆、接地等全部工作内容
A23: 21 | B23: 1.2.5 | C23: 高位料仓 | D23: 各种规格、各种型号、各种材质 | E23: 吨 | F23: 15 | I23: 7691.5802 | J23: 3910 | K23: 2150 | L23: 115373.7 | M23: 58650 | N23: 32250 | P23: 同上
A24: 22 | B24: 1.2.6 | C24: 平台隔热喷涂料 | D24: 隔热板下部及侧向外表面喷涂 50mm厚隔热材料, 要求耐火度不小于700度，材料容重不大于1t/m3 | E24: m³ | F24: 25 | I24: 4678.28 | J24: 2200 | K24: 1500 | L24: 116957 | M24: 55000 | N24: 37500 | P24: 供货、接货、开箱清点、场内运输、检、试验、（含外观、理化等检、试验）、铺贴喷隔热材料及配套的固定件、清理表面等全部工作内容
A25: 23 | B25: 1.2.7 | C25: 耐火砖 | D25: 高铝砖、硅碳砖‌、镁碳砖；1550℃ | E25: 立方米 | F25: 30 | I25: 2275.92 | J25: 1500 | K25: 300 | L25: 68277.6 | M25: 45000 | N25: 9000 | P25: 供货，接货、开箱清点、运输、检（试）验、（含外观、理化等检、试验）、砌筑（含预砌筑、预组装、选砖、机械集中磨砖、机械集中切砖）、二次勾缝吹风清扫、镶铁件、模板装拆等全部工作内容
A26: 24 | B26: 1.3 | C26: 脱硫站轨道及基础 | I26: 0 | J26: 0 | K26: 0 | L26: 0 | M26: 0 | N26: 0
A27: 25 | B27: 1.3.1 | C27: 轨道基础 | D27: C30(钢筋单列) | E27: 立方米 | F27: 495 | I27: 901.55955 | J27: 260 | K27: 235 | L27: 446271.98 | M27: 128700 | N27: 116325 | P27: 降水、排水、挖填运土石方(含特殊爆破)、基础垫层、模板安拆堆放、截（接）桩头、填桩芯、预埋铁件（含钢管、套筒、防雷接地极、地脚螺栓等）制安、砼浇捣养护、脚手架搭拆、铁件刷油、浇灌（灌浆）、固定架制安等全部工作内容
A28: 26 | B28: 1.3.2 | C28: 轨道基础钢筋 | D28: 各种规格、各种型号、各种材质 | E28: 吨 | F28: 59.4 | I28: 5161 | J28: 3250 | K28: 850 | L28: 306563.4 | M28: 193050 | N28: 50490 | P28: 钢筋采购、制作、运输、绑扎安装等全部工作内容
A29: 27 | B29: 1.3.3 | C29: 地面钢轨 | D29: 各种规格、各种型号、各种材质 | E29: 吨 | F29: 23.27 | I29: 8055.235 | J29: 4600 | K29: 1300 | L29: 187445.32 | M29: 107042 | N29: 30251 | P29: 矫直、切割、坡口、吊装、手下工焊接、找正、连接接头、压轨器(含主材)供货及安装、车挡制作、接地安装等全部工作内容
A30: 28 | B30: 1.3.4 | C30: 电缆卷筒钢平台 | D30: 各种规格、各种型号、各种材质 | E30: 吨 | F30: 2 | I30: 7551.5786 | J30: 3910 | K30: 2150 | L30: 15103.157 | M30: 7820 | N30: 4300 | P30: 钢结构设计详图设计、材料供货、除锈防腐、制作、探伤、运输、卸车、拼装、吊装、安装、涂漆、接地等全部工作内容
A31: 29 | B31: 1.4 | C31: 新建参观通道 | I31: 0 | J31: 0 | K31: 0 | L31: 0 | M31: 0 | N31: 0
A32: 30 | B32: 1.4.1 | C32: 精炼炉及脱硫走道钢平台 | D32: 各种规格、各种型号、各种材质 | E32: 吨 | F32: 14 | I32: 7551.5786 | J32: 3910 | K32: 2150 | L32: 105722.1 | M32: 54740 | N32: 30100 | P32: 钢结构设计详图设计、材料供货、除锈防腐、制作、探伤、运输、卸车、拼装、吊装、安装、涂漆、接地等全部工作内容
A33: 31 | B33: 1.4.2 | C33: 屋面彩板 | D33: 0.8厚V125彩钢板 | E33: 平方米 | F33: 60 | I33: 127.02185 | J33: 72 | K33: 22 | L33: 7621.3109 | M33: 4320 | N33: 1320 | P33: 墙屋面板(含异型板、零配件)排版、制作、运输、安装等施工图、施工规范要求的全部工作内容
A34: 32 | B34: 1.4.3 | C34: 墙面彩板 | D34: 0.6厚V125彩钢板 | E34: 平方米 | F34: 30 | I34: 115.60868 | J34: 63.5 | K34: 22 | L34: 3468.2604 | M34: 1905 | N34: 660 | P34: 同上
A35: 33 | B35: 1.4.4 | C35: 钢化玻璃隔断 | D35: 单层钢化玻璃，不小于6mm | E35: 平方米 | F35: 120 | I35: 584.19756 | J35: 330 | K35: 120 | L35: 70103.707 | M35: 39600 | N35: 14400 | P35: 供货、运输、安装、调试等全部工作内容
A36: 34 | B36: 1.5 | C36: 建筑小房 | I36: 0 | J36: 0 | K36: 0 | L36: 0 | M36: 0 | N36: 0
A37: 35 | B37: 1.5.1 | C37: 液压站 | D37: 砖混结构 | E37: 平方米 | F37: 47.25 | I37: 2640.0224 | J37: 800 | K37: 680 | L37: 124741.06 | M37: 37800 | N37: 32130 | P37: 降水、排水、土石方(含特殊爆破)挖运填、基础、截（接）桩头、桩锚筋、桩锚板、PHC桩混凝土填芯、基坑支护、钢筋供货及制安、混凝土结构（含构件）、砌体及其涂料，楼面顶棚涂料，楼面、屋面及其防水、防火、隔热、保温层，门窗，地面防潮层，地面铺砌、预埋铁件、预埋管道、钢构件、钢结构KMD设计、脚手架，界面剂，伸缩缝，隔断，踢脚线、散水、坡道、装修及零星构筑物(如电缆沟及其盖板)等全部土建工作内容及照明(包括照明电缆电线、配管、灯具、整流器（断路器、触发器）、开关、插座、照明箱等主材供货及安装等) 、防雷接地、室内外给排水（含淋浴、洗脸盆、污水池、大小便器、管道等），空调电源线路、弱电线路及插座等全部工作内容
A38: 36 | B38: 1.5.2 | C38: 操作室（精装修） | D38: 砖混结构 | E38: 平方米 | F38: 63 | I38: 2892.9024 | J38: 800 | K38: 680 | L38: 182252.85 | M38: 50400 | N38: 42840 | P38: 同上
A39: 37 | B39: 1.5.3 | C39: 电气室 | D39: 砖混结构 | E39: 平方米 | F39: 126 | I39: 3019.3424 | J39: 800 | K39: 680 | L39: 380437.15 | M39: 100800 | N39: 85680 | P39: 同上
A40: 38 | B40: 1.5.4 | C40: 工具、休息间 | D40: 砖混结构 | E40: 平方米 | F40: 28.35 | I40: 2387.1424 | J40: 800 | K40: 580 | L40: 67675.488 | M40: 22680 | N40: 16443 | P40: 同上
...

Sheet Sheet2
A1: 序号 | B1: (多项)
A3: 工程或费用名称 | B3: 求和项:总计 | C3: 平均值项:综合单价 | D3: 求和项:主材单价 | E3: 求和项:人工费
A4: 脱硫站平台钢结构 | B4: 2958644.1 | C4: 7251.5786 | D4: 3510 | E4: 2150
A5: 脱硫主厂房钢结构 | B5: 1515579.9 | C5: 7251.5786 | D5: 3510 | E5: 2150
A6: 以上钢筋 | B6: 836082 | C6: 5161 | D6: 9750 | E6: 2550
A7: 风管 | B7: 603897.81 | C7: 9290.7356 | D7: 4060 | E7: 2600
A8: 钻孔灌注桩 | B8: 602270.36 | C8: 823.89926 | D8: 275 | E8: 100
A9: 钢烟囱 | B9: 492417.25 | C9: 7694.0195 | D9: 3911 | E9: 2151
A10: 脱硫站平台钢筋混凝土框架 | B10: 470902.75 | C10: 1499.6903 | D10: 570.75 | E10: 415
A11: 轨道基础 | B11: 446271.98 | C11: 901.55955 | D11: 260 | E11: 235
A12: 铁路路基碎石换填 | B12: 441073.3 | C12: 122.52036 | D12: 82 | E12: 5
A13: 电气室 | B13: 380437.15 | C13: 3019.3424 | D13: 800 | E13: 680
A14: 外墙彩板 | B14: 368802.57 | C14: 108.15325 | D14: 50.5 | E14: 22
A15: 管道支架钢结构 | B15: 362578.93 | C15: 7251.5786 | D15: 3510 | E15: 2150
... A26: 操作室（精装修） | B26: 182252.85 | C26: 2892.9024 | D26: 800 | E26: 680
A27: 动力电缆 ZR-YJV-0.6/1kV | B27: 175724.49 | C27: 13.404466 | E27: 172.5
A28: 钢基铜导体滑触线 | B28: 165916.44 | C28: 691.31851 | D28: 350 | E28: 100
A29: 镀锌钢管 | B29: 160772.48 | C29: 9070.152 | D29: 28200 | E29: 15600
A30: 拆除两套脱硫设施钢平台 | B30: 159314.4 | C30: 796.572 | D30: 0 | E30: 600
A31: 拆除除尘管道 | B31: 158425.32 | C31: 929.334 | D31: 0 | E31: 1400
A32: 新建钢筋混凝土排水沟 | B32: 153031.35 | C32: 1020.209 | D32: 260 | E32: 335
A33: 新建道路 | B33: 148800 | C33: 248 | D33: 56.35 | E33: 35
A34: 拆除旧除尘器基础 | B34: 135417.24 | C34: 225.6954 | D34: 0 | E34: 20
A35: 无缝钢管 | B35: 130779.46 | C35: 6745.5621 | D35: 13530 | E35: 7820
A36: 液压站 | B36: 124741.06 | C36: 2640.0224 | D36: 800 | E36: 680
A37: 拆除铁运线原脱硫平台下混凝土 | B37: 118715.78 | C37: 225.6954 | D37: 0 | E37: 20
A38: 平台隔热喷涂料 | B38: 116957 | C38: 4678.28 | D38: 2200 | E38: 1500
A39: 高位料仓 | B39: 115373.7 | C39: 7691.5802 | D39: 3910 | E39: 2150
A40: 耐高温屏蔽控制电缆 ZR-KGGRP-500 | B40: 111216.96 | C40: 7.1595342 | E40: 46
A41: 烟囱基础 | B41: 109844.36 | C41: 784.60255 | D41: 260 | E41: 192.5
A42: 拆除倒罐站钢平台拆除 | B42: 106209.6 | C42: 1062.096 | D42: 0 | E42: 800
A43: 精炼炉及脱硫走道钢平台 | B43: 105722.1 | C43: 7551.5786 | D43: 3910 | E43: 2150
A44: 脱硫平台柱基础 | B44: 101998.33 | C44: 784.60255 | D44: 260 | E44: 192.5
A45: 墙面彩钢板拆除 | B45: 100368.07 | C45: 26.5524 | D45: 0 | E45: 20
A46: TPO防水卷材 | B46: 99756.066 | C46: 64.015136 | D46: 41 | E46: 10
A47: 不锈钢液压中间配管 | B47: 97999.657 | C47: 39199.863 | D47: 30000 | E47: 3800
A48: 脱硫厂房基础 | B48: 95328.198 | C48: 794.40165 | D48: 260 | E48: 192.5
A49: 耐火砖 | B49: 89202.33 | C49: 2300.445 | D49: 3000 | E49: 600
A50: 铁路土路基压实 | B50: 87500 | C50: 25 | D50: 0 | E50: 5
A51: 高密度聚乙烯（HDPE）缠绕埋地管 | B51: 87160.633 | C51: 577.73668 | D51: 1170 | E51: 245
...
